Workbook

Sheet 1.Guideline
B2: From>> | C2: Internal Audit Department
B3: User>> | C3: Station and Depot Operations
B4: Date of issue>> | C4: 43831
B6: Objective | C6: The objective of this template is to aid the Station Managers in balancing and reporting the Sales/Cash and Stock position of the Station on a monthly basis. It will also assist the Station Manager in carrying out a Self review of the Station activities for the month for the purpose of reporting an accurate position of the Station's lodgement, Expenses, Stock, Product received and Consumptions to the various stakeholders.
B8: Instruction | C8: 1. This report should be sent to the Internal Audit department not later than 4 working days after the end of the reporting month. For example, the report for September 2018 should be sent latest by 4th of October 2018. 2. This template is a replica of the Station record (The daily Sales, Expenses, Stock, Lodgment, Product received and Consumption book). Thus, at every point, the data captured herein must agree with what is captured in the Station record. 3.Sheet 2 (Sales/Cash Reconciliaition) contains the Sales/Cash reconciliation and must be balanced before sending it for review to the Internal Audit department. 4.At no point should there be any difference between the data captured in this template and what is captured in the Station book. This will be reviewed during audit visit for any discrepancy/inconsistency. 5.Sheet 3 (Stock Position) has figures that are linked and protected and as such no data should be keyed-in apart from the respective month and period. The sheet 3 is the result of the stock position of the Station at the end of the month. 6.Some of the rows are protected expecially the ones highlighted in "Yellow"..PLEASE do not bother to populate those cells as they have been formularised and protected to prevent any alteration or modification. 7. Sheet 2 and 3 (Highlighted in yellow) shows the result of the Station of the month in terms of Sales/cash and Stock respectively. These sheets must be balanced before sending for review on a monthly basis.
B10: Audit Contact | C10: All the sheets must be populated with accurate figure in order to determine the Actual Cash and Stock Position of the Station on a monthly basis. This template will be used by the Internal Auditor in carrying out a detailed audit of the Stations activities for the respective months. If you require any clarification on how to navigate the template, kindly reach out to any of the Internal Auditors. John Oruh---08056799340 Edmond Anifowose--08035127657 Evelyn Chukwulobe--08060109252

Sheet 2. Sales>>Cash Position
B3: STATION NAME: | C3: LUCKY WAY | D3: CASH/SALES RECONCILIATION AS AT 01/03/2026 - 17/03/2026
B5: Period of Audit | C5: 10/07/2023- 16/07/2023
B7: 1 | C7: PMS Sales for the Period
B8: Meter reading | C8: Opening (01/03/2026) | D8: Closing (17/03/2026) | F8: Price | G8: Amount
B10: PMS 1 | C10: 945281 | D10: 945479 | E10: =D10-C10 -> 198 | F10: 850 | G10: =E10*F10 -> 168300
B11: PMS 2 | C11: 913277 | D11: 913278 | E11: =D11-C11 -> 1 | F11: 850 | G11: =E11*F11 -> 850
B12: PMS 3 | C12: 1361945 | D12: 1365359 | E12: =D12-C12 -> 3414 | F12: 850 | G12: =E12*F12 -> 2901900
B13: PMS 4 | C13: 1149584 | D13: 1149584 | E13: =D13-C13 -> 0 | F13: 850 | G13: =E13*F13 -> 0
B14: PMS 5 | C14: 1213393 | D14: 1214846 | E14: =D14-C14 -> 1453 | F14: 850 | G14: =E14*F14 -> 1235050
B15: PMS 6 | C15: 1040351 | D15: 1041765 | E15: =D15-C15 -> 1414 | F15: 850 | G15: =E15*F15 -> 1201900
B16: PMS 7 | C16: 1012522 | D16: 1012522 | E16: =D16-C16 -> 0 | F16: 850 | G16: =E16*F16 -> 0
B17: PMS 8 | C17: 1145146 | D17: 1148333 | E17: =D17-C17 -> 3187 | F17: 850 | G17: =E17*F17 -> 2708950
E18: =D18-C18 -> 0 | G18: =E18*F18 -> 0
B19: PMS 1 | C19: 945479 | D19: 947628 | E19: =D19-C19 -> 2149 | F19: 950 | G19: =E19*F19 -> 2041550
B20: PMS 2 | C20: 913278 | D20: 913374 | E20: =D20-C20 -> 96 | F20: 950 | G20: =E20*F20 -> 91200
B21: PMS 3 | C21: 1365359 | D21: 1370607 | E21: =D21-C21 -> 5248 | F21: 950 | G21: =E21*F21 -> 4985600
B22: PMS 4 | C22: 1149584 | D22: 1151178 | E22: =D22-C22 -> 1594 | F22: 950 | G22: =E22*F22 -> 1514300
B23: PMS 5 | C23: 1214846 | D23: 1215271 | E23: =D23-C23 -> 425 | F23: 950 | G23: =E23*F23 -> 403750
B24: PMS 6 | C24: 1041765 | D24: 1044332 | E24: =D24-C24 -> 2567 | F24: 950 | G24: =E24*F24 -> 2438650
B25: PMS 7 | C25: 1012522 | D25: 1012522 | E25: =D25-C25 -> 0 | F25: 950 | G25: =E25*F25 -> 0
B26: PMS 8 | C26: 1148333 | D26: 1153635 | E26: =D26-C26 -> 5302 | F26: 950 | G26: =E26*F26 -> 5036900
E27: =D27-C27 -> 0 | G27: =E27*F27 -> 0
B28: PMS 1 | C28: 947628 | D28: 947748 | E28: =D28-C28 -> 120 | F28: 1025 | G28: =E28*F28 -> 123000
B29: PMS 2 | C29: 913374 | D29: 913374 | E29: =D29-C29 -> 0 | F29: 1025 | G29: =E29*F29 -> 0
B30: PMS 3 | C30: 1370607 | D30: 1371332 | E30: =D30-C30 -> 725 | F30: 1025 | G30: =E30*F30 -> 743125
B31: PMS 4 | C31: 1151178 | D31: 1151178 | E31: =D31-C31 -> 0 | F31: 1025 | G31: =E31*F31 -> 0
B32: PMS 5 | C32: 1215271 | D32: 1215271 | E32: =D32-C32 -> 0 | F32: 1025 | G32: =E32*F32 -> 0
B33: PMS 6 | C33: 1044332 | D33: 1044332 | E33: =D33-C33 -> 0 | F33: 1025 | G33: =E33*F33 -> 0
B34: PMS 7 | C34: 1012522 | D34: 1012522 | E34: =D34-C34 -> 0 | F34: 1025 | G34: =E34*F34 -> 0
B35: PMS 8 | C35: 1153635 | D35: 1154445 | E35: =D35-C35 -> 810 | F35: 1025 | G35: =E35*F35 -> 830250
E36: =D36-C36 -> 0 | G36: =E36*F36 -> 0
B37: PMS 1 | C37: 947748 | D37: 948707 | E37: =D37-C37 -> 959 | F37: 1050 | G37: =E37*F37 -> 1006950
B38: PMS 2 | C38: 913374 | D38: 913374 | E38: =D38-C38 -> 0 | F38: 1050 | G38: =E38*F38 -> 0
B39: PMS 3 | C39: 1371332 | D39: 1372215 | E39: =D39-C39 -> 883 | F39: 1050 | G39: =E39*F39 -> 927150
B40: PMS 4 | C40: 1151178 | D40: 1151178 | E40: =D40-C40 -> 0 | F40: 1050 | G40: =E40*F40 -> 0
B41: PMS 5 | C41: 1215271 | D41: 1215271 | E41: =D41-C41 -> 0 | F41: 1050 | G41: =E41*F41 -> 0
B42: PMS 6 | C42: 1044332 | D42: 1044332 | E42: =D42-C42 -> 0 | F42: 1050 | G42: =E42*F42 -> 0
B43: PMS 7 | C43: 1012522 | D43: 1012523 | E43: =D43-C43 -> 1 | F43: 1050 | G43: =E43*F43 -> 1050
B44: PMS 8 | C44: 1154445 | D44: 1155521 | E44: =D44-C44 -> 1076 | F44: 1050 | G44: =E44*F44 -> 1129800
E45: =D45-C45 -> 0 | G45: =E45*F45 -> 0
...

Sheet 3.Stock Position
C2: AUDIT REPORT FOR : LUCKY WAY
C3: STOCK POSITION FOR THE PERIOD (01/03/2026- 17/03/2026)
C6: PMS STOCK POSITION | D6: Per Manager's Computation
C7: OPENING STOCK (01/03/2026) | D7: 43950
C9: SUPPLIES DURING THE PERIOD | D9: 44600
C11: STOCK AVAILABLE FOR SALE | D11: 88550
C13: CLOSING STOCK (17/03/2026) | D13: 20500
C15: QUANTITY SOLD | D15: 68100
C17: QUANTITY DISPENSED | D17: 68455
C19: OVERAGE/(SHORTAGE) | D19: 355
C23: EXPECTED LITRES | D23: 0
C25: ACTUAL LITRES RECEIVED | D25: 44600
C27: OVERAGE/(SHORTAGE) - TRUCK DRIVER | D27: 44600
C32: AGO STOCK POSITION | D32: Per Manager's Computation
C33: OPENING STOCK (01/03/2026) | D33: 10750
C35: SUPPLIES DURING THE PERIOD | D35: 14800
C37: STOCK AVAILABLE FOR SALE | D37: 25550
C39: CLOSING STOCK (17/03/2026) | D39: 34400
C41: QUANTITY SOLD | D41: -20000
C43: QUANTITY DISPENSED | D43: 5770
C45: OVERAGE/(SHORTAGE) | D45: 25770
C49: EXPECTED LITRES | D49: 0
C51: ACTUAL LITRES RECEIVED | D51: 14800
C53: OVERAGE/(SHORTAGE) - TRUCK DRIVER | D53: 14800
C59: DPK STOCK POSITION | D59: Per Manager's Computation
C60: OPENING STOCK (01/03/2026) | D60: 1100
C62: SUPPLIES DURING THE PERIOD | D62: 0
C64: STOCK AVAILABLE FOR SALE | D64: 1100
C66: CLOSING STOCK (17/03/2026) | D66: 1100
C68: QUANTITY SOLD | D68: 0
C70: QUANTITY DISPENSED | D70: 0
C72: OVERAGE/(SHORTAGE) | D72: 0
C76: EXPECTED LITRES | D76: 0
C78: ACTUAL LITRES RECEIVED | D78: 0
C80: OVERAGE/(SHORTAGE) - TRUCK DRIVER | D80: 0

Sheet 4.Lodgement Sheet
B2: Name of Station | C2: LUCKY WAY
B3: Date of Preparation
B4: For>> | C4: Internal Audit
B8: SALES DATE | C8: TOTAL SALES | E8: CASH SALES | G8: CREDIT SALES | I8: ANALYSIS OF POS BY BANKS | Q8: P.O.S | R8: EXPENSES | S8: EXPECTED LODGEMENT | T8: ACTUAL LODGEMENT | U8: TELLER NO | V8: LODGEMENT DATE | W8: AREA MANAGERS COMMENT
I9: STANBIC | J9: STANBIC | K9: STANBIC | Q9: Total POS
B11: 46081.958 | C11: =E11+G11+Q11 -> 4134620 | E11: 588104 | I11: 1091855 | J11: 909300 | K11: 1545361 | Q11: =I11+J11+K11+L11+M11+N11+O11+P11 -> 3546516 | S11: =E11-R11 -> 588104
C12: =E12+G12+Q12 -> 0 | Q12: =I12+J12+K12+L12+M12+N12+O12+P12 -> 0 | S12: =E12-R12 -> 0 | T12: 0 | V12: 46081.958
C13: =E13+G13+Q13 -> 0 | Q13: =I13+J13+K13+L13+M13+N13+O13+P13 -> 0 | S13: =E13-R13 -> 0
B14: 46082.958 | C14: =E14+G14+Q14 -> 4443440 | E14: 152735 | I14: 1344855 | J14: 1415940 | K14: 1529910 | Q14: =I14+J14+K14+L14+M14+N14+O14+P14 -> 4290705 | S14: =E14-R14 -> 152735
C15: =E15+G15+Q15 -> 0 | Q15: =I15+J15+K15+L15+M15+N15+O15+P15 -> 0 | S15: =E15-R15 -> 0 | T15: 0 | V15: 46082.958
C16: =E16+G16+Q16 -> 0 | Q16: =I16+J16+K16+L16+M16+N16+O16+P16 -> 0 | S16: =E16-R16 -> 0
B17: 46083.958 | C17: =E17+G17+Q17 -> 4212500 | E17: 188601 | I17: 1182858 | J17: 1214600 | K17: 1626441 | Q17: =I17+J17+K17+L17+M17+N17+O17+P17 -> 4023899 | S17: =E17-R17 -> 188601
C18: =E18+G18+Q18 -> 0 | Q18: =I18+J18+K18+L18+M18+N18+O18+P18 -> 0 | S18: =E18-R18 -> 0 | T18: 0 | V18: 46083.958
C19: =E19+G19+Q19 -> 0 | Q19: =I19+J19+K19+L19+M19+N19+O19+P19 -> 0 | S19: =E19-R19 -> 0
B20: 46084.958 | C20: =E20+G20+Q20 -> 4878900 | E20: 199084 | I20: 2137691 | J20: 1293287 | K20: 1248838 | Q20: =I20+J20+K20+L20+M20+N20+O20+P20 -> 4679816 | S20: =E20-R20 -> 199084
C21: =E21+G21+Q21 -> 0 | Q21: =I21+J21+K21+L21+M21+N21+O21+P21 -> 0 | S21: =E21-R21 -> 0 | T21: 0 | V21: 46084.958
C22: =E22+G22+Q22 -> 0 | Q22: =I22+J22+K22+L22+M22+N22+O22+P22 -> 0 | S22: =E22-R22 -> 0
B23: 46085.958 | C23: =E23+G23+Q23 -> 4694870 | E23: 1029079 | I23: 831197 | J23: 1717020 | K23: 1117574 | Q23: =I23+J23+K23+L23+M23+N23+O23+P23 -> 3665791 | S23: =E23-R23 -> 1029079
C24: =E24+G24+Q24 -> 0 | Q24: =I24+J24+K24+L24+M24+N24+O24+P24 -> 0 | S24: =E24-R24 -> 0 | T24: 0 | V24: 46085.958
C25: =E25+G25+Q25 -> 0 | Q25: =I25+J25+K25+L25+M25+N25+O25+P25 -> 0 | S25: =E25-R25 -> 0
B26: 46086.958 | C26: =E26+G26+Q26 -> 6217525 | E26: 986585 | I26: 2010654 | J26: 1700622 | K26: 1519664 | Q26: =I26+J26+K26+L26+M26+N26+O26+P26 -> 5230940 | S26: =E26-R26 -> 986585
C27: =E27+G27+Q27 -> 0 | Q27: =I27+J27+K27+L27+M27+N27+O27+P27 -> 0 | S27: =E27-R27 -> 0 | T27: 0 | V27: 46086.958
C28: =E28+G28+Q28 -> 0 | Q28: =I28+J28+K28+L28+M28+N28+O28+P28 -> 0 | S28: =E28-R28 -> 0
B29: 46087.958 | C29: =E29+G29+Q29 -> 5622062 | E29: 642004 | I29: 2526460 | J29: 749800 | K29: 1703798 | Q29: =I29+J29+K29+L29+M29+N29+O29+P29 -> 4980058 | S29: =E29-R29 -> 642004
C30: =E30+G30+Q30 -> 0 | Q30: =I30+J30+K30+L30+M30+N30+O30+P30 -> 0 | S30: =E30-R30 -> 0 | T30: 0 | V30: 46087.958
C31: =E31+G31+Q31 -> 0 | Q31: =I31+J31+K31+L31+M31+N31+O31+P31 -> 0 | S31: =E31-R31 -> 0
B32: 46088.958 | C32: =E32+G32+Q32 -> 4278630 | E32: 230357 | I32: 2171982 | J32: 0 | K32: 1876291 | Q32: =I32+J32+K32+L32+M32+N32+O32+P32 -> 4048273 | S32: =E32-R32 -> 230357
C33: =E33+G33+Q33 -> 0 | Q33: =I33+J33+K33+L33+M33+N33+O33+P33 -> 0 | S33: =E33-R33 -> 0 | T33: 0 | V33: 46088.958
C34: =E34+G34+Q34 -> 0 | Q34: =I34+J34+K34+L34+M34+N34+O34+P34 -> 0 | S34: =E34-R34 -> 0
B35: 46089.958 | C35: =E35+G35+Q35 -> 4371250 | E35: 526074 | I35: 1456311 | J35: 0 | K35: 2388865 | Q35: =I35+J35+K35+L35+M35+N35+O35+P35 -> 3845176 | S35: =E35-R35 -> 526074
C36: =E36+G36+Q36 -> 0 | Q36: =I36+J36+K36+L36+M36+N36+O36+P36 -> 0 | S36: =E36-R36 -> 0 | T36: 0 | V36: 46089.958
C37: =E37+G37+Q37 -> 0 | Q37: =I37+J37+K37+L37+M37+N37+O37+P37 -> 0 | S37: =E37-R37 -> 0
B38: 46090.958 | C38: =E38+G38+Q38 -> 5930570 | E38: 218723 | I38: 3569487 | J38: 0 | K38: 2142360 | Q38: =I38+J38+K38+L38+M38+N38+O38+P38 -> 5711847 | S38: =E38-R38 -> 218723
C39: =E39+G39+Q39 -> 0 | Q39: =I39+J39+K39+L39+M39+N39+O39+P39 -> 0 | S39: =E39-R39 -> 0 | T39: 0 | V39: 46090.958
C40: =E40+G40+Q40 -> 0 | Q40: =I40+J40+K40+L40+M40+N40+O40+P40 -> 0 | S40: =E40-R40 -> 0
B41: 46091.958 | C41: =E41+G41+Q41 -> 6087330 | E41: 618226 | I41: 2168584 | J41: 0 | K41: 3300520 | Q41: =I41+J41+K41+L41+M41+N41+O41+P41 -> 5469104 | S41: =E41-R41 -> 618226
C42: =E42+G42+Q42 -> 0 | Q42: =I42+J42+K42+L42+M42+N42+O42+P42 -> 0 | S42: =E42-R42 -> 0 | T42: 0 | V42: 46091.958
C43: =E43+G43+Q43 -> 0 | Q43: =I43+J43+K43+L43+M43+N43+O43+P43 -> 0 | S43: =E43-R43 -> 0
B44: 46092.958 | C44: =E44+G44+Q44 -> 5831850 | E44: 574180 | I44: 1135560 | J44: 0 | K44: 4122110 | Q44: =I44+J44+K44+L44+M44+N44+O44+P44 -> 5257670 | S44: =E44-R44 -> 574180
C45: =E45+G45+Q45 -> 0 | Q45: =I45+J45+K45+L45+M45+N45+O45+P45 -> 0 | S45: =E45-R45 -> 0 | T45: 0 | V45: 46092.958
...

Sheet 5.PMS Consumption and Pour back
C2: PMS CONSUMPTION AT DIFFERENT PRICES
B5: Date | C5: Rate (N) | D5: Managers Car | E5: Area Manager's Car | F5: Police/Army | G5: Weight and Measures | H5: EDSTMA | I5: DPR | J5: Vigilante | K5: Others | L5: Security Agents | M5: Pour back
B6: 46081.958 | C6: 850 | D6: 20 | E6: 0
B7: 46090.958 | C7: 1300 | D7: 0 | E7: 0
B8: 46096.958 | C8: 1300 | D8: 0 | E8: 0
D9: 0 | E9: 0
D10: 0 | E10: 0
D11: 0 | E11: 0
D12: 0 | E12: 0
B36: Total | D36: =SUM(D6:D35) -> 20 | E36: =SUM(E6:E35) -> 0 | F36: =SUM(F6:F35) -> 0 | G36: =SUM(G6:G35) -> 0 | H36: =SUM(H6:H35) -> 0 | I36: =SUM(I6:I35) -> 0 | J36: =SUM(J6:J35) -> 0 | K36: =SUM(K6:K35) -> 0 | ... M36: =SUM(M6:M35) -> 0

Sheet 6.AGO Consumption and Pour back
C2: AGO CONSUMPTION AT DIFFERENT PRICES
B5: Date | C5: Rate (N) | D5: Generator | E5: POUR BACK | F5: Taskforce/Ministry of Environment | G5: Weight & Measure/ DPR | H5: PUMP ISSUE | I5: Logistics Trucks
B6: 46081.958 | C6: 990 | D6: 32 | F6: 0 | G6: 0 | H6: 0 | I6: 0
B7: 46082.958 | C7: 990 | D7: 32 | F7: 0 | G7: 0 | H7: 0 | I7: 0
B8: 46083.958 | C8: 1050 | D8: 33 | F8: 0 | G8: 0 | H8: 0 | I8: 0
B9: 46084.958 | C9: 1050 | D9: 32 | F9: 0 | G9: 0 | H9: 0 | I9: 0
B10: 46085.958 | C10: 1180 | D10: 32 | F10: 0 | G10: 0 | H10: 0 | I10: 0
B11: 46086.958 | C11: 1450 | D11: 32 | F11: 0 | G11: 0 | H11: 0 | I11: 0
B12: 46087.958 | C12: 1450 | D12: 40 | F12: 0 | G12: 0 | H12: 0 | I12: 0
B13: 46088.958 | C13: 1450 | D13: 32
B14: 46089.958 | C14: 1770 | D14: 32
B15: 46090.958 | C15: 1770 | D15: 42
B16: 46091.958 | C16: 1770 | D16: 32
B17: 46092.958 | C17: 1770 | D17: 32
B18: 46093.958 | C18: 1700 | D18: 32
B19: 46094.958 | C19: 1700 | D19: 32
B20: 46095.958 | C20: 1700 | D20: 32
B21: 46096.958 | C21: 1670
B38: Total | D38: =SUM(D6:D37) -> 499 | E38: =SUM(E6:E37) -> 0 | F38: =SUM(F6:F37) -> 0 | G38: =SUM(G6:G37) -> 0 | H38: =SUM(H6:H37) -> 0 | I38: =SUM(I6:I37) -> 0

Sheet 7.DPK Consumption and Pour back
C3: DPK CONSUMPTION AT DIFFERENT PRICES
B6: Date | C6: Rate (N) | D6: Pour back | E6: Police/Army | F6: Taskforce/Ministry of Environment | G6: Weight & Measure/ DPR | H6: Vigilante | I6: Others
E7: 0 | F7: 0 | G7: 0 | H7: 0 | I7: 0
E8: 0 | F8: 0 | G8: 0 | H8: 0 | I8: 0
E9: 0 | F9: 0 | G9: 0 | H9: 0 | I9: 0
E10: 0 | F10: 0 | G10: 0 | H10: 0 | I10: 0
E11: 0 | F11: 0 | G11: 0 | H11: 0 | I11: 0
E12: 0 | F12: 0 | G12: 0 | H12: 0 | I12: 0
E13: 0 | F13: 0 | G13: 0 | H13: 0 | I13: 0
B37: Total | D37: =SUM(D7:D27) -> 0 | E37: =SUM(E7:E27) -> 0 | F37: =SUM(F7:F27) -> 0 | G37: =SUM(G7:G27) -> 0 | H37: =SUM(H7:H27) -> 0 | I37: =SUM(I7:I27) -> 0

Sheet 8.Product Received
F5: PRODUCT RECEIVED FOR THE MONTH
B7: LOADING | C7: RECEIPT | D7: PMS | I7: AGO | N7: DPK
B8: DATE | C8: DATE | D8: EXPECTED | F8: ACTUAL | I8: EXPECTED | K8: ACTUAL | N8: EXPECTED | P8: ACTUAL
B9: 46081.958 | C9: 46081.958 | K9: 14800 | O9: 0
B10: 46089.958 | C10: 46089.958 | F10: 44600
B52: TOTAL | D52: =SUM(D9:D51) -> 0 | F52: =SUM(F9:F51) -> 44600 | I52: =SUM(I9:I51) -> 0 | K52: =SUM(K9:K51) -> 14800 | N52: =SUM(N9:N51) -> 0 | P52: =SUM(P9:P51) -> 0

Sheet 9.Expenses for the Month
D4: EXPENSES FOR THE MONTH
B6: S/N | C6: DATE | D6: PURPOSE OF EXPENSES | E6: AMOUNT (=N=) | F6: APPROVED BY:
B7: 1
B8: 2
B9: 3
B10: 4
B11: 5
B12: 6
B13: 7
B14: 8
B15: 9
B16: 10
B17: 11
B18: 12
... B37: 31
C38: Total | E38: =SUM(E7:E37) -> 0

Sheet 10.Record of Stock Position
B6: PMS | H6: AGO | N6: DPK
B7: Date | C7: Opening Stock | D7: Actual Producted Supplied | E7: Quantity sold | F7: Closing Stock | H7: Date | I7: Opening Stock | J7: Actual Producted Supplied | K7: Quantity sold | L7: Closing Stock | N7: Date | O7: Opening Stock | P7: Actual Producted Supplied | Q7: Quantity sold | R7: Closing Stock
B8: 46081.958 | C8: 43950 | E8: =C8+D8-F8 -> 4750 | F8: 39200 | H8: 46081.958 | I8: 10750 | J8: 14800 | K8: =I8+J8-L8 -> 550 | L8: 25000 | N8: 46081.958 | O8: 1100 | Q8: =O8+P8-R8 -> 0 | R8: 1100
B9: 46082.958 | C9: 39200 | E9: =C9+D9-F9 -> 4900 | F9: 34300 | H9: 46082.958 | I9: 25000 | K9: =I9+J9-L9 -> 500 | L9: 24500 | N9: 46082.958 | O9: 1100 | Q9: =O9+P9-R9 -> 0 | R9: 1100
B10: 46083.958 | C10: 34300 | E10: =C10+D10-F10 -> 4100 | F10: 30200 | H10: 46083.958 | I10: 24500 | K10: =I10+J10-L10 -> 200 | L10: 24300 | N10: 46083.958 | O10: 1100 | Q10: =O10+P10-R10 -> 0 | R10: 1100
B11: 46084.958 | C11: 30200 | E11: =C11+D11-F11 -> 4750 | F11: 25450 | H11: 46084.958 | I11: 24300 | K11: =I11+J11-L11 -> 300 | L11: 24000 | N11: 46084.958 | O11: 1100 | Q11: =O11+P11-R11 -> 0 | R11: 1100
B12: 46085.958 | C12: 25450 | E12: =C12+D12-F12 -> 4400 | F12: 21050 | H12: 46085.958 | I12: 24000 | K12: =I12+J12-L12 -> 300 | L12: 23700 | N12: 46085.958 | O12: 1100 | Q12: =O12+P12-R12 -> 0 | R12: 1100
B13: 46086.958 | C13: 21050 | E13: =C13+D13-F13 -> 5800 | F13: 15250 | H13: 46086.958 | I13: 23700 | K13: =I13+J13-L13 -> 600 | L13: 23100 | N13: 46086.958 | O13: 1100 | Q13: =O13+P13-R13 -> 0 | R13: 1100
B14: 46087.958 | C14: 15250 | E14: =C14+D14-F14 -> 4550 | F14: 10700 | H14: 46087.958 | I14: 23100 | K14: =I14+J14-L14 -> 500 | L14: 22600 | N14: 46087.958 | O14: 1100 | Q14: =O14+P14-R14 -> 0 | R14: 1100
B15: 46088.958 | C15: 10700 | E15: =C15+D15-F15 -> 3700 | F15: 7000 | H15: 46088.958 | I15: 22600 | K15: =I15+J15-L15 -> 100 | L15: 22500 | N15: 46088.958 | O15: 1100 | Q15: =O15+P15-R15 -> 0 | R15: 1100
B16: 46089.958 | C16: 7000 | D16: 44600 | E16: =C16+D16-F16 -> 3400 | F16: 48200 | H16: 46089.958 | I16: 22500 | K16: =I16+J16-L16 -> 200 | L16: 22300 | N16: 46089.958 | O16: 1100 | Q16: =O16+P16-R16 -> 0 | R16: 1100
B17: 46090.958 | C17: 48200 | E17: =C17+D17-F17 -> 4300 | F17: 43900 | H17: 46090.958 | I17: 22300 | K17: =I17+J17-L17 -> 400 | L17: 21900 | N17: 46090.958 | O17: 1100 | Q17: =O17+P17-R17 -> 0 | R17: 1100
B18: 46091.958 | C18: 43900 | E18: =C18+D18-F18 -> 0 | F18: 43900 | H18: 46091.958 | I18: 21900 | K18: =I18+J18-L18 -> 0 | L18: 21900 | N18: 46091.958 | O18: 1100 | Q18: =O18+P18-R18 -> 0 | R18: 1100
B19: 46092.958 | C19: 43950 | E19: =C19+D19-F19 -> 0 | F19: 43950 | H19: 46092.958 | I19: 10750 | K19: =I19+J19-L19 -> 0 | L19: 10750 | N19: 46092.958 | O19: 1100 | Q19: =O19+P19-R19 -> 0 | R19: 1100
B20: 46093.958 | C20: 43950 | E20: =C20+D20-F20 -> 0 | F20: 43950 | H20: 46093.958 | I20: 10750 | K20: =I20+J20-L20 -> 0 | L20: 10750 | N20: 46093.958 | O20: 1100 | Q20: =O20+P20-R20 -> 0 | R20: 1100
B21: 46094.958 | C21: 43950 | E21: =C21+D21-F21 -> 15950 | F21: 28000 | H21: 46094.958 | I21: 10750 | K21: =I21+J21-L21 -> -24150 | L21: 34900 | N21: 46094.958 | O21: 1100 | Q21: =O21+P21-R21 -> 0 | R21: 1100
B22: 46095.958 | C22: 28000 | E22: =C22+D22-F22 -> 3450 | F22: 24550 | H22: 46095.958 | I22: 34900 | K22: =I22+J22-L22 -> 300 | L22: 34600 | N22: 46095.958 | O22: 1100 | Q22: =O22+P22-R22 -> 0 | R22: 1100
B23: 46096.958 | C23: 24550 | E23: =C23+D23-F23 -> 4050 | F23: 20500 | H23: 46096.958 | I23: 34600 | K23: =I23+J23-L23 -> 200 | L23: 34400 | N23: 46096.958 | O23: 1100 | Q23: =O23+P23-R23 -> 0 | R23: 1100
E24: =C24+D24-F24 -> 0 | K24: =I24+J24-L24 -> 0 | Q24: =O24+P24-R24 -> 0
E25: =C25+D25-F25 -> 0 | K25: =I25+J25-L25 -> 0 | Q25: =O25+P25-R25 -> 0
E26: =C26+D26-F26 -> 0 | K26: =I26+J26-L26 -> 0 | Q26: =O26+P26-R26 -> 0
E27: =C27+D27-F27 -> 0 | K27: =I27+J27-L27 -> 0 | Q27: =O27+P27-R27 -> 0
E28: =C28+D28-F28 -> 0 | K28: =I28+J28-L28 -> 0 | Q28: =O28+P28-R28 -> 0
E29: =C29+D29-F29 -> 0 | K29: =I29+J29-L29 -> 0 | Q29: =O29+P29-R29 -> 0
E30: =C30+D30-F30 -> 0 | K30: =I30+J30-L30 -> 0 | Q30: =O30+P30-R30 -> 0
E31: =C31+D31-F31 -> 0 | K31: =I31+J31-L31 -> 0 | Q31: =O31+P31-R31 -> 0
E32: =C32+D32-F32 -> 0 | K32: =I32+J32-L32 -> 0 | Q32: =O32+P32-R32 -> 0
E33: =C33+D33-F33 -> 0 | K33: =I33+J33-L33 -> 0 | Q33: =O33+P33-R33 -> 0
E34: =C34+D34-F34 -> 0 | K34: =I34+J34-L34 -> 0 | Q34: =O34+P34-R34 -> 0
E35: =C35+D35-F35 -> 0 | K35: =I35+J35-L35 -> 0 | Q35: =O35+P35-R35 -> 0
... E38: =C38+D38-F38 -> 0 | K38: =I38+J38-L38 -> 0 | Q38: =O38+P38-R38 -> 0
F40: =IF(C38>0,F38,F37) -> 0 | L40: =IF(I38>0,L38,L37) -> 0 | R40: =IF(O38>0,R38,R37) -> 0

Sheet Customers' Ledger
A1: CORPORATE CUSTOMERS STATEMENT FOR THE MONTH
A2: S/N | B2: CUSTOMER'S NAME | C2: OPENING BALANCE | E2: LODGEMENT DATE | F2: BANK | G2: AMOUNT LODGED | I2: VALUE OF PRODUCT SOLD | J2: CLOSING BALANCE
A3: 1 | J3: =C3+G3-I3 -> 0
J4: =C4+G4-I4 -> 0
J5: =C5+G5-I5 -> 0
J6: =C6+G6-I6 -> 0
J7: =C7+G7-I7 -> 0
J8: =C8+G8-I8 -> 0
J9: =C9+G9-I9 -> 0
A10: 2 | J10: =C10+G10-I10 -> 0
J11: =C11+G11-I11 -> 0
J12: =C12+G12-I12 -> 0
J13: =C13+G13-I13 -> 0
J14: =C14+G14-I14 -> 0
J15: =C15+G15-I15 -> 0
J16: =C16+G16-I16 -> 0
A17: 3 | J17: =C17+G17-I17 -> 0
J18: =C18+G18-I18 -> 0
J19: =C19+G19-I19 -> 0
J20: =C20+G20-I20 -> 0
J21: =C21+G21-I21 -> 0
J22: =C22+G22-I22 -> 0
J23: =C23+G23-I23 -> 0
J24: =C24+G24-I24 -> 0
J25: =C25+G25-I25 -> 0
J26: =C26+G26-I26 -> 0
J27: =C27+G27-I27 -> 0
J28: =C28+G28-I28 -> 0
J29: =C29+G29-I29 -> 0
... J42: =C42+G42-I42 -> 0
B43: TOTAL | C43: =SUM(C3:C42) -> 0 | G43: =SUM(G3:G42) -> 0 | I43: =SUM(I3:I42) -> 0 | J43: =SUM(J3:J42) -> 0

Sheet Castro Lubricants
B3: LUBRICANTS AS AT 17/03/2026 - LUCKY WAY
B4: S/N | C4: ITEM | D4: Litre | E4: OPENING STOCK | F4: PURCHASE | G4: SALES (QUANTITY) | H4: CLOSING STOCK | I4: PRICE (N) | J4: AMOUNT | K4: Date
B5: 1 | C5: RAINOIL SUPREME | D5: 4 | G5: =E5+F5-H5 -> 0 | J5: =G5*I5 -> 0
B6: 2 | C6: RAINOIL UNIVERSAL SAE 40 | D6: 4 | G6: =E6+F6-H6 -> 0 | J6: =G6*I6 -> 0
B7: 3 | C7: RAINOIL UNIVERSAL SAE 40 | D7: 25 | G7: =E7+F7-H7 -> 0 | J7: =G7*I7 -> 0
B8: 4 | C8: MAGNATEC 10W-40 | D8: 4 | G8: =E8+F8-H8 -> 0 | J8: =G8*I8 -> 0
B9: 5 | C9: INJECTOR CLEANER | D9: 0.35 | E9: 0 | G9: =E9+F9-H9 -> 0 | H9: 0 | I9: 0 | J9: =G9*I9 -> 0
B10: 6 | C10: MAGNATEC 5W-30 | D10: 1 | G10: =E10+F10-H10 -> 0 | J10: =G10*I10 -> 0
B11: 7 | C11: MAGNATEC 5W-30 | D11: 4 | G11: =E11+F11-H11 -> 0 | J11: =G11*I11 -> 0
B12: 8 | C12: MAGNATEC 5W-30 A5 | D12: 5 | E12: 0 | G12: =E12+F12-H12 -> 0 | H12: 0 | I12: 0 | J12: =G12*I12 -> 0
B13: 9 | C13: RAINOIL SUPREME | D13: 1 | G13: =E13+F13-H13 -> 0 | J13: =G13*I13 -> 0
B14: 10 | C14: RADICOOL | D14: 5 | E14: 0 | G14: =E14+F14-H14 -> 0 | H14: 0 | I14: 0 | J14: =G14*I14 -> 0
B15: 11 | C15: BRAKE FLUID DOT 4 | D15: 0.2 | G15: =E15+F15-H15 -> 0 | J15: =G15*I15 -> 0
B16: 12 | C16: BRAKE FLUID DOT 4 | D16: 0.5 | G16: =E16+F16-H16 -> 0 | J16: =G16*I16 -> 0
B17: 13 | C17: GT X ESSENTIAL 20W-50 | D17: 1 | G17: =E17+F17-H17 -> 0 | J17: =G17*I17 -> 0
B18: 14 | C18: GT X ESSENTIAL 20W-50 | D18: 4 | G18: =E18+F18-H18 -> 0 | J18: =G18*I18 -> 0
B19: 15 | C19: POWER RACING 40 10W-50 | D19: 1 | E19: 0 | G19: =E19+F19-H19 -> 0 | H19: 0 | I19: 0 | J19: =G19*I19 -> 0
B20: 16 | C20: MOTOR OIL SAE 40 | D20: 4 | E20: 0 | G20: =E20+F20-H20 -> 0 | H20: 0 | I20: 0 | J20: =G20*I20 -> 0
B21: 17 | C21: EDGE PROFESSIONAL | D21: 1 | E21: 0 | G21: =E21+F21-H21 -> 0 | H21: 0 | I21: 0 | J21: =G21*I21 -> 0
B22: 18 | C22: GT X ESSENTIAL 15W-40 | D22: 4 | G22: =E22+F22-H22 -> 0 | J22: =G22*I22 -> 0
B23: 19 | C23: GT X ESSENTIAL 15W-40 | D23: 5 | G23: =E23+F23-H23 -> 0 | J23: =G23*I23 -> 0
B24: 20 | C24: POWER MAX HD-40 (RETAIL OIL) | D24: 1 | E24: 0 | G24: =E24+F24-H24 -> 0 | H24: 0 | I24: 0 | J24: =G24*I24 -> 0
B25: 21 | C25: ATF DEX II | D25: 1 | E25: 0 | G25: =E25+F25-H25 -> 0 | H25: 0 | I25: 0 | J25: =G25*I25 -> 0
G26: =E26+F26-H26 -> 0
G27: =E27+F27-H27 -> 0
G28: =E28+F28-H28 -> 0
G29: =E29+F29-H29 -> 0
E30: =SUM(E5:E29) -> 0 | F30: =SUM(F5:F29) -> 0 | G30: =SUM(G5:G29) -> 0 | H30: =SUM(H5:H29) -> 0 | I30: TOTAL | J30: =SUM(J5:J29) -> 0
I31: LODGED
I32: LODGED
I33: LODGED
I34: LODGED
I35: LODGED
J36: =J30-SUM(J31:J35) -> 0

Sheet Sheet1 (2)
B2: Name of Station
B3: Prepared By | S3: 502405
B4: Date of Preparation
B7: SALES DATE | C7: TOTAL SALES | E7: CASH SALES | G7: CREDIT SALES | I7: ANALYSIS OF POS BY BANKS | Q7: P.O.S | R7: EXPENSES | S7: EXPECTED LODGEMENT | T7: ACTUAL LODGEMENT | U7: Teller No | V7: LODGEMENT DATE
I8: Zenith Bank | J8: Diamond Bank | K8: Stanbic Bank | L8: GT Bank | M8: Providus Bank | N8: Access Bank | O8: Fidelity Bank | P8: First Bank | Q8: Total POS
B10: 43106 | C10: =E10+G10+Q10 -> 1961845 | E10: 1459440 | G10: 0 | I10: 0 | J10: 0 | K10: 0 | L10: 0 | M10: 0 | N10: 0 | O10: 0 | P10: 0 | Q10: 502405 | R10: 30000 | S10: =E10-R10 -> 1429440 | T10: 307490 | U10: 5038530 | V10: 43106
C11: =E11+G11+Q11 -> 0 | S11: =E11-R11 -> 0 | T11: 524300 | U11: 5038529 | V11: 43106
C12: =E12+G12+Q12 -> 0 | S12: =E12-R12 -> 0 | T12: 597650 | U12: 5038532 | V12: 43196
C13: =E13+G13+Q13 -> 0 | S13: =E13-R13 -> 0
B14: 43137 | C14: =E14+G14+Q14 -> 2067145 | E14: 1202620 | G14: 0 | I14: 0 | J14: 0 | K14: 0 | L14: 0 | M14: 0 | N14: 0 | O14: 0 | P14: 0 | Q14: 864525 | S14: =E14-R14 -> 1202620 | T14: 1202620 | U14: 5038531 | V14: 43196
C15: =E15+G15+Q15 -> 0 | S15: =E15-R15 -> 0
B16: 43165 | C16: =E16+G16+Q16 -> 1357955 | E16: 910521 | G16: 0 | I16: 0 | J16: 0 | K16: 0 | L16: 0 | M16: 0 | N16: 0 | O16: 0 | P16: 0 | Q16: 447434 | S16: =E16-R16 -> 910521 | T16: 910525 | U16: 5038533 | V16: 43196
C17: =E17+G17+Q17 -> 0 | S17: =E17-R17 -> 0
B18: 43196 | C18: =E18+G18+Q18 -> 2025435 | E18: 1224445 | G18: 0 | I18: 0 | J18: 0 | K18: 0 | L18: 0 | M18: 0 | N18: 0 | O18: 0 | P18: 0 | Q18: 800990 | R18: 36000 | S18: =E18-R18 -> 1188445 | T18: 571040 | U18: 5038534 | V18: 43196
C19: =E19+G19+Q19 -> 0 | S19: =E19-R19 -> 0 | T19: 617405 | U19: 5038535 | V19: 43226
C20: =E20+G20+Q20 -> 0 | S20: =E20-R20 -> 0
B21: 43226 | C21: =E21+G21+Q21 -> 2205080 | E21: 1231510 | G21: 0 | I21: 0 | J21: 0 | K21: 0 | L21: 0 | M21: 0 | N21: 0 | O21: 0 | P21: 0 | Q21: 973570 | S21: =E21-R21 -> 1231510 | T21: 279120 | U21: 5038537 | V21: 43226
C22: =E22+G22+Q22 -> 0 | S22: =E22-R22 -> 0 | T22: 300500 | U22: 5038536 | V22: 43226
C23: =E23+G23+Q23 -> 0 | S23: =E23-R23 -> 0 | T23: 651890 | U23: 5038538 | V23: 43257
C24: =E24+G24+Q24 -> 0 | S24: =E24-R24 -> 0
B25: 43257 | C25: =E25+G25+Q25 -> 1781840 | E25: 987460 | G25: 0 | I25: 0 | J25: 0 | K25: 0 | L25: 0 | M25: 0 | N25: 0 | O25: 0 | P25: 0 | Q25: 794380 | R25: 12500 | S25: =E25-R25 -> 974960 | T25: 312500 | U25: 5038539 | V25: 43257
C26: =E26+G26+Q26 -> 0 | S26: =E26-R26 -> 0 | T26: 215420 | U26: 5038540 | V26: 43257
C27: =E27+G27+Q27 -> 0 | S27: =E27-R27 -> 0 | T27: 447040 | U27: 5038542 | V27: 43287
C28: =E28+G28+Q28 -> 0 | S28: =E28-R28 -> 0
B29: 43287 | C29: =E29+G29+Q29 -> 1807640 | E29: 1232600 | G29: 0 | I29: 0 | J29: 0 | K29: 0 | L29: 0 | M29: 0 | Q29: 575040 | S29: =E29-R29 -> 1232600 | T29: 376000 | U29: 5038541 | V29: 43287
C30: =E30+G30+Q30 -> 0 | S30: =E30-R30 -> 0 | T30: 311235 | U30: 5038543 | V30: 43287
C31: =E31+G31+Q31 -> 0 | S31: =E31-R31 -> 0 | T31: 545365 | U31: 5038544 | V31: 43318
C32: =E32+G32+Q32 -> 0 | S32: =E32-R32 -> 0
B33: 43318 | C33: =E33+G33+Q33 -> 1852585 | E33: 1201029 | G33: 0 | I33: 0 | J33: 0 | K33: 0 | L33: 0 | M33: 0 | N33: 0 | O33: 0 | P33: 0 | Q33: 651556 | S33: =E33-R33 -> 1201029 | T33: 356800 | U33: 5038545 | V33: 43318
C34: =E34+G34+Q34 -> 0 | S34: =E34-R34 -> 0 | T34: 313300 | U34: 5038546 | V34: 43318
C35: =E35+G35+Q35 -> 0 | S35: =E35-R35 -> 0 | T35: 530930 | U35: 5038549 | V35: 43410
C36: =E36+G36+Q36 -> 0 | S36: =E36-R36 -> 0
B37: 43349 | C37: =E37+G37+Q37 -> 1970430 | E37: 882220 | G37: 0 | I37: 0 | J37: 0 | K37: 0 | L37: 0 | M37: 0 | N37: 0 | O37: 0 | P37: 0 | Q37: 1088210 | S37: =E37-R37 -> 882220 | T37: 882220 | U37: 5038547 | V37: 43045
C38: =E38+G38+Q38 -> 0 | S38: =E38-R38 -> 0
B39: 43379 | C39: =E39+G39+Q39 -> 2053260 | E39: 1420738 | G39: 0 | I39: 0 | J39: 0 | K39: 0 | L39: 0 | M39: 0 | N39: 0 | O39: 0 | P39: 0 | Q39: 632522 | S39: =E39-R39 -> 1420738 | T39: 1420740 | U39: 5038548 | V39: 43410
C40: =E40+G40+Q40 -> 0 | S40: =E40-R40 -> 0
B41: 43410 | C41: =E41+G41+Q41 -> 2331550 | E41: 1241913 | G41: 0 | I41: 0 | J41: 0 | K41: 0 | L41: 0 | M41: 0 | N41: 0 | O41: 0 | P41: 0 | Q41: 1089637 | S41: =E41-R41 -> 1241913 | T41: 383645 | U41: 5038550 | V41: 43410
C42: =E42+G42+Q42 -> 0 | S42: =E42-R42 -> 0 | T42: 383890 | U42: 5038551 | V42: 43410
C43: =E43+G43+Q43 -> 0 | S43: =E43-R43 -> 0 | T43: 474380 | U43: 5038552 | V43: 43440
C44: =E44+G44+Q44 -> 0 | S44: =E44-R44 -> 0
...
