Workbook

Sheet 1.Guideline
B2: From>> | C2: Internal Audit Department
B3: User>> | C3: Station and Depot Operations
B4: Date of issue>> | C4: 43830.958
B6: Objective | C6: The objective of this report is to present the Sales/Cash and Stock position of the Station on a weekly basis.
B8: Instruction | C8: 1. This report should be completed and submitted on a weekly basis. For example, the report for the week should be submitted by Monday of the following week. 2. This template is divided into the following sheets: Sheet 2 (Sales/Cash Position) contains the Sales/Cash position reconciliation. Sheet 3 (Stock Position) has figures that are auto-generated from other sheets. Cells highlighted in "Yellow" are formula cells. ..PLEASE do not bother to edit such cells.
B10: Audit Contact | C10: All the sheets must be filled in to show the Cash and Stock Position of the Station on a weekly basis.

Sheet 2. Sales>>Cash Position
B3: STATION NAME: | D3: CASH/SALES RECONCILIATION AS AT 01/03/2026 - 18/03/2026
B5: Period of Audit | C5: 01/03/2026- 18/03/2026
B7: 1 | C7: PMS Sales for the Period
B8: Meter reading | C8: Opening (01/03/2026) | D8: Closing (18/03/2026) | F8: Price | G8: Amount
B10: PMS 1 | C10: 945281 | D10: 945479 | E10: =D10-C10 -> 198 | F10: 850 | G10: =E10*F10 -> 168300
B11: PMS 2 | C11: 913277 | D11: 913278 | E11: =D11-C11 -> 1 | F11: 850 | G11: =E11*F11 -> 850
B12: PMS 3 | C12: 1361945 | D12: 1365359 | E12: =D12-C12 -> 3414 | F12: 850 | G12: =E12*F12 -> 2901900
B13: PMS 4 | C13: 1149584 | D13: 1149584 | E13: =D13-C13 -> 0 | F13: 850 | G13: =E13*F13 -> 0
B14: PMS 5 | C14: 1213393 | D14: 1214846 | E14: =D14-C14 -> 1453 | F14: 850 | G14: =E14*F14 -> 1235050
B15: PMS 6 | C15: 1040351 | D15: 1041765 | E15: =D15-C15 -> 1414 | F15: 850 | G15: =E15*F15 -> 1201900
B16: PMS 7 | C16: 1012522 | D16: 1012522 | E16: =D16-C16 -> 0 | F16: 850 | G16: =E16*F16 -> 0
B17: PMS 8 | C17: 1145146 | D17: 1148333 | E17: =D17-C17 -> 3187 | F17: 850 | G17: =E17*F17 -> 2708950
B19: PMS 1 | C19: 945479 | D19: 947628 | E19: =D19-C19 -> 2149 | F19: 950 | G19: =E19*F19 -> 2041550
B20: PMS 2 | C20: 913278 | D20: 913374 | E20: =D20-C20 -> 96 | F20: 950 | G20: =E20*F20 -> 91200
B21: PMS 3 | C21: 1365359 | D21: 1370607 | E21: =D21-C21 -> 5248 | F21: 950 | G21: =E21*F21 -> 4985600
B22: PMS 4 | C22: 1149584 | D22: 1151178 | E22: =D22-C22 -> 1594 | F22: 950 | G22: =E22*F22 -> 1514300
... B89: PMS 8 | C89: 1164809 | D89: 1168342 | E89: =D89-C89 -> 3533 | F89: 1300 | G89: =E89*F89 -> 4592900
B91: A | C91: Total PMS sales for the period | E91: =SUM(E10:E89) -> 68455 | G91: =SUM(G10:G89) -> 74558937
B93: B | C93: Less Pourback on PMS for the Period | G93: =E93*F93 -> 0
G94: =E94*F94 -> 0
G95: =E95*F95 -> 0
G96: =E96*F96 -> 0
G97: =E97*F97 -> 0
B98: C=A-B | C98: Net PMS sales for the period | E98: =E91-SUM(E93:E97) -> 68455 | G98: =G91-SUM(G93:G97) -> 74558937
C100: Less Consumption on PMS
C101: Manager Car | E101: 50 | F101: 850 | G101: =E101*F101 -> 42500
C102: Manager Car | E102: 100 | F102: 1300 | G102: =E102*F102 -> 130000
G103: =E103*F103 -> 0
G104: =E104*F104 -> 0
G105: =E105*F105 -> 0
G106: =E106*F106 -> 0
G107: =E107*F107 -> 0
G108: =E108*F108 -> 0
G109: =E109*F109 -> 0
G110: =E110*F110 -> 0
G111: =E111*F111 -> 0
G112: =E112*F112 -> 0
B113: D | C113: Total Consumption of PMS for the Period | E113: =SUM(E101:E112) -> 150 | G113: =SUM(G101:G112) -> 172500
B115: E=C-D | C115: Expected PMS Sales for the period | E115: =E98-E113 -> 68305 | G115: =G98-G113 -> 74386437
B119: 2 | C119: AGO Sales for the Period
...

Sheet 3.Stock Position
C2: AUDIT REPORT FOR : STATION
C3: STOCK POSITION FOR THE PERIOD (01/03/2026- 18/03/2026)
C6: PMS STOCK POSITION | D6: Per Manager's Computation
C7: OPENING STOCK (01/03/2026) | D7: ='10.Record of Stock Position'!C8 -> 43950
C9: SUPPLIES DURING THE PERIOD | D9: ='8.Product Received'!F52 -> 44600
C11: STOCK AVAILABLE FOR SALE | D11: =+D7+D9 -> 88550
C13: CLOSING STOCK (18/03/2026) | D13: ='10.Record of Stock Position'!F40 -> 20500
C15: QUANTITY SOLD | D15: =D11-D13 -> 68050
C17: QUANTITY DISPENSED | D17: ='2. Sales>>Cash Position'!E98 -> 68455
C19: OVERAGE/(SHORTAGE) | D19: =D17-D15 -> 405
C23: EXPECTED LITRES | D23: ='8.Product Received'!D52 -> 0
C25: ACTUAL LITRES RECEIVED | D25: ='8.Product Received'!F52 -> 44600
C27: OVERAGE/(SHORTAGE) - TRUCK DRIVER | D27: =D25-D23 -> 44600
C33: AGO STOCK POSITION | D33: Per Manager's Computation
C34: OPENING STOCK (01/03/2026) | D34: ='10.Record of Stock Position'!I8 -> 10750
C36: SUPPLIES DURING THE PERIOD | D36: ='8.Product Received'!K52 -> 14800
C38: STOCK AVAILABLE FOR SALE | D38: =+D34+D36 -> 25550
C40: CLOSING STOCK (18/03/2026) | D40: ='10.Record of Stock Position'!L40 -> 34400
C42: QUANTITY SOLD | D42: =D38-D40 -> -8850
C44: QUANTITY DISPENSED | D44: ='2. Sales>>Cash Position'!E159 -> 5770
C46: OVERAGE/(SHORTAGE) | D46: =D44-D42 -> 14620
C50: EXPECTED LITRES | D50: ='8.Product Received'!I52 -> 0
C52: ACTUAL LITRES RECEIVED | D52: ='8.Product Received'!K52 -> 14800
C54: OVERAGE/(SHORTAGE) - TRUCK DRIVER | D54: =D52-D50 -> 14800
C60: DPK STOCK POSITION | D60: Per Manager's Computation
C61: OPENING STOCK (01/03/2026) | D61: ='10.Record of Stock Position'!O8 -> 1100
C63: SUPPLIES DURING THE PERIOD | D63: ='8.Product Received'!P52 -> 0
C65: STOCK AVAILABLE FOR SALE | D65: =+D61+D63 -> 1100
C67: CLOSING STOCK (18/03/2026) | D67: ='10.Record of Stock Position'!R40 -> 1100
C69: QUANTITY SOLD | D69: =D65-D67 -> 0
C71: QUANTITY DISPENSED | D71: ='2. Sales>>Cash Position'!E193 -> 0
C73: OVERAGE/(SHORTAGE) | D73: =D71-D69 -> 0
C77: EXPECTED LITRES | D77: ='8.Product Received'!N52 -> 0
C79: ACTUAL LITRES RECEIVED | D79: ='8.Product Received'!P52 -> 0
C81: OVERAGE/(SHORTAGE) - TRUCK DRIVER | D81: =D79-D77 -> 0

Sheet 4.Lodgement Sheet
B2: Name of Station | C2: BRANCH
B3: Date of Preparation
B4: For>> | C4: Internal Audit
B8: SALES DATE | C8: TOTAL SALES | E8: CASH SALES | G8: CREDIT SALES | I8: ANALYSIS OF POS BY BANKS | P8: P.O.S | Q8: EXPENSES | R8: EXPECTED LODGEMENT | S8: ACTUAL LODGEMENT | T8: TELLER NO | U8: LODGEMENT DATE | V8: AREA MANAGERS COMMENT
I9: STANBIC | J9: STANBIC | K9: STANBIC | P9: Total POS
B11: 46081.958 | C11: =E11+G11+P11 -> 4134620 | E11: 588104 | I11: 1091855 | J11: 909300 | K11: 1545361 | P11: =SUM(I11:O11) -> 3546516 | R11: =E11-Q11 -> 588104 | T11: POS | U11: 46081.958
C12: =E12+G12+P12 -> 0 | P12: =SUM(I12:O12) -> 0 | R12: =E12-Q12 -> 0 | S12: 4134620 | T12: E-BILL
C13: =E13+G13+P13 -> 0 | P13: =SUM(I13:O13) -> 0 | R13: =E13-Q13 -> 0
B14: 46082.958 | C14: =E14+G14+P14 -> 4443440 | E14: 152735 | I14: 1344855 | J14: 1415940 | K14: 1529910 | P14: =SUM(I14:O14) -> 4290705 | R14: =E14-Q14 -> 152735 | T14: POS | U14: 46082.958
C15: =E15+G15+P15 -> 0 | P15: =SUM(I15:O15) -> 0 | R15: =E15-Q15 -> 0 | S15: 4443440 | T15: E-BILL
C16: =E16+G16+P16 -> 0 | P16: =SUM(I16:O16) -> 0 | R16: =E16-Q16 -> 0
B17: 46083.958 | C17: =E17+G17+P17 -> 4212500 | E17: 188601 | I17: 1182858 | J17: 1214600 | K17: 1626441 | P17: =SUM(I17:O17) -> 4023899 | R17: =E17-Q17 -> 188601 | T17: POS | U17: 46083.958
C18: =E18+G18+P18 -> 0 | P18: =SUM(I18:O18) -> 0 | R18: =E18-Q18 -> 0 | S18: 4212500 | T18: E-BILL
C19: =E19+G19+P19 -> 0 | P19: =SUM(I19:O19) -> 0 | R19: =E19-Q19 -> 0
B20: 46084.958 | C20: =E20+G20+P20 -> 4878900 | E20: 199084 | I20: 2137691 | J20: 1293287 | K20: 1248838 | P20: =SUM(I20:O20) -> 4679816 | R20: =E20-Q20 -> 199084 | T20: POS | U20: 46084.958
C21: =E21+G21+P21 -> 0 | P21: =SUM(I21:O21) -> 0 | R21: =E21-Q21 -> 0 | S21: 4878900 | T21: E-BILL
C22: =E22+G22+P22 -> 0 | P22: =SUM(I22:O22) -> 0 | R22: =E22-Q22 -> 0
B23: 46085.958 | C23: =E23+G23+P23 -> 4694870 | E23: 1029079 | I23: 831197 | J23: 1717020 | K23: 1117574 | P23: =SUM(I23:O23) -> 3665791 | R23: =E23-Q23 -> 1029079 | T23: POS | U23: 46085.958
C24: =E24+G24+P24 -> 0 | P24: =SUM(I24:O24) -> 0 | R24: =E24-Q24 -> 0 | S24: 4694870 | T24: E-BILL
C25: =E25+G25+P25 -> 0 | P25: =SUM(I25:O25) -> 0 | R25: =E25-Q25 -> 0
B26: 46086.958 | C26: =E26+G26+P26 -> 6217525 | E26: 986585 | I26: 2010654 | J26: 1700622 | K26: 1519664 | P26: =SUM(I26:O26) -> 5230940 | R26: =E26-Q26 -> 986585 | T26: POS | U26: 46086.958
C27: =E27+G27+P27 -> 0 | P27: =SUM(I27:O27) -> 0 | R27: =E27-Q27 -> 0 | S27: 6217525 | T27: E-BILL
C28: =E28+G28+P28 -> 0 | P28: =SUM(I28:O28) -> 0 | R28: =E28-Q28 -> 0
B29: 46087.958 | C29: =E29+G29+P29 -> 5622062 | E29: 642004 | I29: 2526460 | J29: 749800 | K29: 1703798 | P29: =SUM(I29:O29) -> 4980058 | R29: =E29-Q29 -> 642004 | T29: POS | U29: 46087.958
C30: =E30+G30+P30 -> 0 | P30: =SUM(I30:O30) -> 0 | R30: =E30-Q30 -> 0 | S30: 5622062 | T30: E-BILL
C31: =E31+G31+P31 -> 0 | P31: =SUM(I31:O31) -> 0 | R31: =E31-Q31 -> 0
B32: 46088.958 | C32: =E32+G32+P32 -> 4278630 | E32: 230357 | I32: 2171982 | J32: 0 | K32: 1876291 | P32: =SUM(I32:O32) -> 4048273 | R32: =E32-Q32 -> 230357 | T32: POS | U32: 46088.958
C33: =E33+G33+P33 -> 0 | P33: =SUM(I33:O33) -> 0 | R33: =E33-Q33 -> 0 | S33: 4278630 | T33: E-BILL
C34: =E34+G34+P34 -> 0 | P34: =SUM(I34:O34) -> 0 | R34: =E34-Q34 -> 0
B35: 46089.958 | C35: =E35+G35+P35 -> 4371250 | E35: 526074 | I35: 1456311 | J35: 0 | K35: 2388865 | P35: =SUM(I35:O35) -> 3845176 | R35: =E35-Q35 -> 526074 | T35: POS | U35: 46089.958
C36: =E36+G36+P36 -> 0 | P36: =SUM(I36:O36) -> 0 | R36: =E36-Q36 -> 0 | S36: 4371250 | T36: E-BILL
C37: =E37+G37+P37 -> 0 | P37: =SUM(I37:O37) -> 0 | R37: =E37-Q37 -> 0
B38: 46090.958 | C38: =E38+G38+P38 -> 5930570 | E38: 218723 | I38: 3569487 | J38: 0 | K38: 2142360 | P38: =SUM(I38:O38) -> 5711847 | R38: =E38-Q38 -> 218723 | T38: POS | U38: 46090.958
C39: =E39+G39+P39 -> 0 | P39: =SUM(I39:O39) -> 0 | R39: =E39-Q39 -> 0 | S39: 5930570 | T39: E-BILL
C40: =E40+G40+P40 -> 0 | P40: =SUM(I40:O40) -> 0 | R40: =E40-Q40 -> 0
B41: 46091.958 | C41: =E41+G41+P41 -> 6087330 | E41: 618226 | I41: 2168584 | J41: 0 | K41: 3300520 | P41: =SUM(I41:O41) -> 5469104 | R41: =E41-Q41 -> 618226 | T41: POS | U41: 46091.958
C42: =E42+G42+P42 -> 0 | P42: =SUM(I42:O42) -> 0 | R42: =E42-Q42 -> 0 | S42: 6087330 | T42: E-BILL
C43: =E43+G43+P43 -> 0 | P43: =SUM(I43:O43) -> 0 | R43: =E43-Q43 -> 0
B44: 46092.958 | C44: =E44+G44+P44 -> 5831850 | E44: 574180 | I44: 1135560 | J44: 0 | K44: 4122110 | P44: =SUM(I44:O44) -> 5257670 | R44: =E44-Q44 -> 574180 | T44: POS | U44: 46092.958
C45: =E45+G45+P45 -> 0 | P45: =SUM(I45:O45) -> 0 | R45: =E45-Q45 -> 0 | S45: 5831850 | T45: E-BILL
...

Sheet 5.PMS Consumption and Pour back
C2: PMS CONSUMPTION AT DIFFERENT PRICES
B5: Date | C5: Rate (N) | D5: Area Manager Car | E5: Army | F5: DPR | G5: DSS OFFICIALS | H5: EDSTMA | I5: Generator | J5: LOGISTICS | K5: Logistics Truck | L5: Manager Car | M5: MDS Logistics Truck | N5: Others | O5: Police | P5: Police/Army | Q5: Pour Back | R5: Pour Back After Pump Repairs | S5: Regional Manager Car | T5: Security Agents | U5: Vigilante | V5: Weight and Measures | W5: Pour back
B6: 46081.958 | C6: 850 | D6: 0 | E6: 0 | F6: 0 | G6: 0 | H6: 0 | I6: 0 | J6: 0 | K6: 0 | L6: 50 | M6: 0 | N6: 0 | O6: 0 | P6: 0 | Q6: 0 | R6: 0 | S6: 0 | T6: 0 | U6: 0 | V6: 0 | W6: 0
B7: 46082.958 | C7: 850 | D7: 0 | E7: 0 | F7: 0 | G7: 0 | H7: 0 | I7: 0 | J7: 0 | K7: 0 | L7: 0 | M7: 0 | N7: 0 | O7: 0 | P7: 0 | Q7: 0 | R7: 0 | S7: 0 | T7: 0 | U7: 0 | V7: 0 | W7: 0
B8: 46083.958 | C8: 950 | D8: 0 | E8: 0 | F8: 0 | G8: 0 | H8: 0 | I8: 0 | J8: 0 | K8: 0 | L8: 0 | M8: 0 | N8: 0 | O8: 0 | P8: 0 | Q8: 0 | R8: 0 | S8: 0 | T8: 0 | U8: 0 | V8: 0 | W8: 0
B9: 46084.958 | C9: 950 | D9: 0 | E9: 0 | F9: 0 | G9: 0 | H9: 0 | I9: 0 | J9: 0 | K9: 0 | L9: 0 | M9: 0 | N9: 0 | O9: 0 | P9: 0 | Q9: 0 | R9: 0 | S9: 0 | T9: 0 | U9: 0 | V9: 0 | W9: 0
B10: 46085.958 | C10: 950 | D10: 0 | E10: 0 | F10: 0 | G10: 0 | H10: 0 | I10: 0 | J10: 0 | K10: 0 | L10: 0 | M10: 0 | N10: 0 | O10: 0 | P10: 0 | Q10: 0 | R10: 0 | S10: 0 | T10: 0 | U10: 0 | V10: 0 | W10: 0
B11: 46086.958 | C11: 1025 | D11: 0 | E11: 0 | F11: 0 | G11: 0 | H11: 0 | I11: 0 | J11: 0 | K11: 0 | L11: 0 | M11: 0 | N11: 0 | O11: 0 | P11: 0 | Q11: 0 | R11: 0 | S11: 0 | T11: 0 | U11: 0 | V11: 0 | W11: 0
B12: 46087.958 | C12: 1082 | D12: 0 | E12: 0 | F12: 0 | G12: 0 | H12: 0 | I12: 0 | J12: 0 | K12: 0 | L12: 0 | M12: 0 | N12: 0 | O12: 0 | P12: 0 | Q12: 0 | R12: 0 | S12: 0 | T12: 0 | U12: 0 | V12: 0 | W12: 0
B13: 46088.958 | C13: 1082 | D13: 0 | E13: 0 | F13: 0 | G13: 0 | H13: 0 | I13: 0 | J13: 0 | K13: 0 | L13: 0 | M13: 0 | N13: 0 | O13: 0 | P13: 0 | Q13: 0 | R13: 0 | S13: 0 | T13: 0 | U13: 0 | V13: 0 | W13: 0
B14: 46089.958 | C14: 1240 | D14: 0 | E14: 0 | F14: 0 | G14: 0 | H14: 0 | I14: 0 | J14: 0 | K14: 0 | L14: 0 | M14: 0 | N14: 0 | O14: 0 | P14: 0 | Q14: 0 | R14: 0 | S14: 0 | T14: 0 | U14: 0 | V14: 0 | W14: 0
B15: 46090.958 | C15: 1300 | D15: 0 | E15: 0 | F15: 0 | G15: 0 | H15: 0 | I15: 0 | J15: 0 | K15: 0 | L15: 50 | M15: 0 | N15: 0 | O15: 0 | P15: 0 | Q15: 0 | R15: 0 | S15: 0 | T15: 0 | U15: 0 | V15: 0 | W15: 0
B16: 46091.958 | C16: 1200 | D16: 0 | E16: 0 | F16: 0 | G16: 0 | H16: 0 | I16: 0 | J16: 0 | K16: 0 | L16: 0 | M16: 0 | N16: 0 | O16: 0 | P16: 0 | Q16: 0 | R16: 0 | S16: 0 | T16: 0 | U16: 0 | V16: 0 | W16: 0
B17: 46092.958 | C17: 1200 | D17: 0 | E17: 0 | F17: 0 | G17: 0 | H17: 0 | I17: 0 | J17: 0 | K17: 0 | L17: 0 | M17: 0 | N17: 0 | O17: 0 | P17: 0 | Q17: 0 | R17: 0 | S17: 0 | T17: 0 | U17: 0 | V17: 0 | W17: 0
... B23: 46098.958 | C23: 1300 | D23: 0 | E23: 0 | F23: 0 | G23: 0 | H23: 0 | I23: 0 | J23: 0 | K23: 0 | L23: 0 | M23: 0 | N23: 0 | O23: 0 | P23: 0 | Q23: 0 | R23: 0 | S23: 0 | T23: 0 | U23: 0 | V23: 0 | W23: 0
B37: Total | D37: 0 | E37: 0 | F37: 0 | G37: 0 | H37: 0 | I37: 0 | J37: 0 | K37: 0 | L37: 150 | M37: 0 | N37: 0 | O37: 0 | P37: 0 | Q37: 0 | R37: 0 | S37: 0 | T37: 0 | U37: 0 | V37: 0 | W37: 0

Sheet 6.AGO Consumption and Pour back
C2: AGO CONSUMPTION AT DIFFERENT PRICES
B5: Date | C5: Rate (N) | D5: Area Manager Car | E5: Army | F5: DPR | G5: DSS OFFICIALS | H5: EDSTMA | I5: Generator | J5: Generator | K5: LOGISTICS | L5: Logistics Truck | M5: Manager Car | N5: MDS Logistics Truck | O5: Others | P5: Police | Q5: Police/Army | R5: Pour Back | S5: Pour Back After Pump Repairs | T5: Regional Manager Car | U5: Security Agents | V5: Vigilante | W5: Weight and Measures | X5: Pour back
B6: 46081.958 | C6: 990 | D6: 0 | E6: 0 | F6: 0 | G6: 0 | H6: 0 | I6: 32 | J6: 0 | K6: 0 | L6: 0 | M6: 0 | N6: 0 | O6: 0 | P6: 0 | Q6: 0 | R6: 0 | S6: 0 | T6: 0 | U6: 0 | V6: 0 | W6: 0 | X6: 0
B7: 46082.958 | C7: 990 | D7: 0 | E7: 0 | F7: 0 | G7: 0 | H7: 0 | I7: 32 | J7: 0 | K7: 0 | L7: 0 | M7: 0 | N7: 0 | O7: 0 | P7: 0 | Q7: 0 | R7: 0 | S7: 0 | T7: 0 | U7: 0 | V7: 0 | W7: 0 | X7: 0
B8: 46083.958 | C8: 1050 | D8: 0 | E8: 0 | F8: 0 | G8: 0 | H8: 0 | I8: 33 | J8: 0 | K8: 0 | L8: 0 | M8: 0 | N8: 0 | O8: 0 | P8: 0 | Q8: 0 | R8: 0 | S8: 0 | T8: 0 | U8: 0 | V8: 0 | W8: 0 | X8: 0
B9: 46084.958 | C9: 1050 | D9: 0 | E9: 0 | F9: 0 | G9: 0 | H9: 0 | I9: 32 | J9: 0 | K9: 0 | L9: 0 | M9: 0 | N9: 0 | O9: 0 | P9: 0 | Q9: 0 | R9: 0 | S9: 0 | T9: 0 | U9: 0 | V9: 0 | W9: 0 | X9: 0
B10: 46085.958 | C10: 1180 | D10: 0 | E10: 0 | F10: 0 | G10: 0 | H10: 0 | I10: 32 | J10: 0 | K10: 0 | L10: 0 | M10: 0 | N10: 0 | O10: 0 | P10: 0 | Q10: 0 | R10: 0 | S10: 0 | T10: 0 | U10: 0 | V10: 0 | W10: 0 | X10: 0
B11: 46086.958 | C11: 1450 | D11: 0 | E11: 0 | F11: 0 | G11: 0 | H11: 0 | I11: 32 | J11: 0 | K11: 0 | L11: 0 | M11: 0 | N11: 0 | O11: 0 | P11: 0 | Q11: 0 | R11: 0 | S11: 0 | T11: 0 | U11: 0 | V11: 0 | W11: 0 | X11: 0
B12: 46087.958 | C12: 1450 | D12: 0 | E12: 0 | F12: 0 | G12: 0 | H12: 0 | I12: 40 | J12: 0 | K12: 0 | L12: 0 | M12: 0 | N12: 0 | O12: 0 | P12: 0 | Q12: 0 | R12: 0 | S12: 0 | T12: 0 | U12: 0 | V12: 0 | W12: 0 | X12: 0
B13: 46088.958 | C13: 1450 | D13: 0 | E13: 0 | F13: 0 | G13: 0 | H13: 0 | I13: 32 | J13: 0 | K13: 0 | L13: 0 | M13: 0 | N13: 0 | O13: 0 | P13: 0 | Q13: 0 | R13: 0 | S13: 0 | T13: 0 | U13: 0 | V13: 0 | W13: 0 | X13: 0
B14: 46089.958 | C14: 1770 | D14: 0 | E14: 0 | F14: 0 | G14: 0 | H14: 0 | I14: 32 | J14: 0 | K14: 0 | L14: 0 | M14: 0 | N14: 0 | O14: 0 | P14: 0 | Q14: 0 | R14: 0 | S14: 0 | T14: 0 | U14: 0 | V14: 0 | W14: 0 | X14: 0
B15: 46090.958 | C15: 1770 | D15: 0 | E15: 0 | F15: 0 | G15: 0 | H15: 0 | I15: 42 | J15: 0 | K15: 0 | L15: 0 | M15: 0 | N15: 0 | O15: 0 | P15: 0 | Q15: 0 | R15: 0 | S15: 0 | T15: 0 | U15: 0 | V15: 0 | W15: 0 | X15: 0
B16: 46091.958 | C16: 1770 | D16: 0 | E16: 0 | F16: 0 | G16: 0 | H16: 0 | I16: 32 | J16: 0 | K16: 0 | L16: 0 | M16: 0 | N16: 0 | O16: 0 | P16: 0 | Q16: 0 | R16: 0 | S16: 0 | T16: 0 | U16: 0 | V16: 0 | W16: 0 | X16: 0
B17: 46092.958 | C17: 1770 | D17: 0 | E17: 0 | F17: 0 | G17: 0 | H17: 0 | I17: 32 | J17: 0 | K17: 0 | L17: 0 | M17: 0 | N17: 0 | O17: 0 | P17: 0 | Q17: 0 | R17: 0 | S17: 0 | T17: 0 | U17: 0 | V17: 0 | W17: 0 | X17: 0
... B23: 46098.958 | C23: 1670 | D23: 0 | E23: 0 | F23: 0 | G23: 0 | H23: 0 | I23: 0 | J23: 0 | K23: 0 | L23: 0 | M23: 0 | N23: 0 | O23: 0 | P23: 0 | Q23: 0 | R23: 0 | S23: 0 | T23: 0 | U23: 0 | V23: 0 | W23: 0 | X23: 0
B37: Total | D37: 0 | E37: 0 | F37: 0 | G37: 0 | H37: 0 | I37: 499 | J37: 32 | K37: 0 | L37: 0 | M37: 0 | N37: 0 | O37: 0 | P37: 0 | Q37: 0 | R37: 0 | S37: 0 | T37: 0 | U37: 0 | V37: 0 | W37: 0 | X37: 0

Sheet 7.DPK Consumption and Pour back
C3: DPK CONSUMPTION AT DIFFERENT PRICES
B6: Date | C6: Rate (N) | D6: Area Manager Car | E6: Army | F6: DPR | G6: DSS OFFICIALS | H6: EDSTMA | I6: Generator | J6: LOGISTICS | K6: Logistics Truck | L6: Manager Car | M6: MDS Logistics Truck | N6: Others | O6: Police | P6: Police/Army | Q6: Pour Back | R6: Pour Back After Pump Repairs | S6: Regional Manager Car | T6: Security Agents | U6: Vigilante | V6: Weight and Measures | W6: Pour back
B7: 46081.958 | C7: 1450 | D7: 0 | E7: 0 | F7: 0 | G7: 0 | H7: 0 | I7: 0 | J7: 0 | K7: 0 | L7: 0 | M7: 0 | N7: 0 | O7: 0 | P7: 0 | Q7: 0 | R7: 0 | S7: 0 | T7: 0 | U7: 0 | V7: 0 | W7: 0
B8: 46082.958 | C8: 1450 | D8: 0 | E8: 0 | F8: 0 | G8: 0 | H8: 0 | I8: 0 | J8: 0 | K8: 0 | L8: 0 | M8: 0 | N8: 0 | O8: 0 | P8: 0 | Q8: 0 | R8: 0 | S8: 0 | T8: 0 | U8: 0 | V8: 0 | W8: 0
B9: 46083.958 | C9: 1450 | D9: 0 | E9: 0 | F9: 0 | G9: 0 | H9: 0 | I9: 0 | J9: 0 | K9: 0 | L9: 0 | M9: 0 | N9: 0 | O9: 0 | P9: 0 | Q9: 0 | R9: 0 | S9: 0 | T9: 0 | U9: 0 | V9: 0 | W9: 0
B10: 46084.958 | C10: 1450 | D10: 0 | E10: 0 | F10: 0 | G10: 0 | H10: 0 | I10: 0 | J10: 0 | K10: 0 | L10: 0 | M10: 0 | N10: 0 | O10: 0 | P10: 0 | Q10: 0 | R10: 0 | S10: 0 | T10: 0 | U10: 0 | V10: 0 | W10: 0
B11: 46085.958 | C11: 1450 | D11: 0 | E11: 0 | F11: 0 | G11: 0 | H11: 0 | I11: 0 | J11: 0 | K11: 0 | L11: 0 | M11: 0 | N11: 0 | O11: 0 | P11: 0 | Q11: 0 | R11: 0 | S11: 0 | T11: 0 | U11: 0 | V11: 0 | W11: 0
B12: 46086.958 | C12: 1450 | D12: 0 | E12: 0 | F12: 0 | G12: 0 | H12: 0 | I12: 0 | J12: 0 | K12: 0 | L12: 0 | M12: 0 | N12: 0 | O12: 0 | P12: 0 | Q12: 0 | R12: 0 | S12: 0 | T12: 0 | U12: 0 | V12: 0 | W12: 0
B13: 46087.958 | C13: 1450 | D13: 0 | E13: 0 | F13: 0 | G13: 0 | H13: 0 | I13: 0 | J13: 0 | K13: 0 | L13: 0 | M13: 0 | N13: 0 | O13: 0 | P13: 0 | Q13: 0 | R13: 0 | S13: 0 | T13: 0 | U13: 0 | V13: 0 | W13: 0
B14: 46088.958 | C14: 1450 | D14: 0 | E14: 0 | F14: 0 | G14: 0 | H14: 0 | I14: 0 | J14: 0 | K14: 0 | L14: 0 | M14: 0 | N14: 0 | O14: 0 | P14: 0 | Q14: 0 | R14: 0 | S14: 0 | T14: 0 | U14: 0 | V14: 0 | W14: 0
B15: 46089.958 | C15: 1450 | D15: 0 | E15: 0 | F15: 0 | G15: 0 | H15: 0 | I15: 0 | J15: 0 | K15: 0 | L15: 0 | M15: 0 | N15: 0 | O15: 0 | P15: 0 | Q15: 0 | R15: 0 | S15: 0 | T15: 0 | U15: 0 | V15: 0 | W15: 0
B16: 46090.958 | C16: 1450 | D16: 0 | E16: 0 | F16: 0 | G16: 0 | H16: 0 | I16: 0 | J16: 0 | K16: 0 | L16: 0 | M16: 0 | N16: 0 | O16: 0 | P16: 0 | Q16: 0 | R16: 0 | S16: 0 | T16: 0 | U16: 0 | V16: 0 | W16: 0
B17: 46091.958 | C17: 1450 | D17: 0 | E17: 0 | F17: 0 | G17: 0 | H17: 0 | I17: 0 | J17: 0 | K17: 0 | L17: 0 | M17: 0 | N17: 0 | O17: 0 | P17: 0 | Q17: 0 | R17: 0 | S17: 0 | T17: 0 | U17: 0 | V17: 0 | W17: 0
B18: 46092.958 | C18: 1450 | D18: 0 | E18: 0 | F18: 0 | G18: 0 | H18: 0 | I18: 0 | J18: 0 | K18: 0 | L18: 0 | M18: 0 | N18: 0 | O18: 0 | P18: 0 | Q18: 0 | R18: 0 | S18: 0 | T18: 0 | U18: 0 | V18: 0 | W18: 0
... B24: 46098.958 | C24: 1450 | D24: 0 | E24: 0 | F24: 0 | G24: 0 | H24: 0 | I24: 0 | J24: 0 | K24: 0 | L24: 0 | M24: 0 | N24: 0 | O24: 0 | P24: 0 | Q24: 0 | R24: 0 | S24: 0 | T24: 0 | U24: 0 | V24: 0 | W24: 0
B38: Total | D38: 0 | E38: 0 | F38: 0 | G38: 0 | H38: 0 | I38: 0 | J38: 0 | K38: 0 | L38: 0 | M38: 0 | N38: 0 | O38: 0 | P38: 0 | Q38: 0 | R38: 0 | S38: 0 | T38: 0 | U38: 0 | V38: 0 | W38: 0

Sheet 8.Product Received
F5: PRODUCT RECEIVED FOR THE MONTH
B7: LOADING | C7: RECEIPT | D7: PMS | I7: AGO | N7: DPK
B8: DATE | C8: DATE | D8: EXPECTED | F8: ACTUAL | I8: EXPECTED | K8: ACTUAL | N8: EXPECTED | P8: ACTUAL
B9: 46081.958 | C9: 46081.958 | K9: 14800
B10: 46089.958 | C10: 46089.958 | F10: 44600
B52: TOTAL | D52: =SUM(D9:D51) -> 0 | F52: =SUM(F9:F51) -> 44600 | I52: =SUM(I9:I51) -> 0 | K52: =SUM(K9:K51) -> 14800 | N52: =SUM(N9:N51) -> 0 | P52: =SUM(P9:P51) -> 0

Sheet 9.Expenses for the Month
D4: EXPENSES FOR THE MONTH
B6: S/N | C6: DATE | D6: PURPOSE OF EXPENSES | E6: AMOUNT (=N=) | F6: APPROVED BY:
B7: 1
B8: 2
B9: 3
B10: 4
B11: 5
B12: 6
B13: 7
B14: 8
B15: 9
B16: 10
B17: 11
B18: 12
... B37: 31
C38: Total | E38: =SUM(E7:E37) -> 0

Sheet 10.Record of Stock Position
B6: PMS | H6: AGO | N6: DPK
B7: Date | C7: Opening Stock | D7: Actual Producted Supplied | E7: Quantity sold | F7: Closing Stock | H7: Date | I7: Opening Stock | J7: Actual Producted Supplied | K7: Quantity sold | L7: Closing Stock | N7: Date | O7: Opening Stock | P7: Actual Producted Supplied | Q7: Quantity sold | R7: Closing Stock
B8: 46081.958 | C8: 43950 | E8: =C8+D8-F8 -> 4750 | F8: 39200 | H8: 46081.958 | I8: 10750 | J8: 14800 | K8: =I8+J8-L8 -> 550 | L8: 25000 | N8: 46081.958 | O8: 1100 | Q8: =O8+P8-R8 -> 0 | R8: 1100
B9: 46082.958 | C9: 39200 | E9: =C9+D9-F9 -> 4900 | F9: 34300 | H9: 46082.958 | I9: 25000 | K9: =I9+J9-L9 -> 500 | L9: 24500 | N9: 46082.958 | O9: 1100 | Q9: =O9+P9-R9 -> 0 | R9: 1100
B10: 46083.958 | C10: 34300 | E10: =C10+D10-F10 -> 4100 | F10: 30200 | H10: 46083.958 | I10: 24500 | K10: =I10+J10-L10 -> 200 | L10: 24300 | N10: 46083.958 | O10: 1100 | Q10: =O10+P10-R10 -> 0 | R10: 1100
B11: 46084.958 | C11: 30200 | E11: =C11+D11-F11 -> 4750 | F11: 25450 | H11: 46084.958 | I11: 24300 | K11: =I11+J11-L11 -> 300 | L11: 24000 | N11: 46084.958 | O11: 1100 | Q11: =O11+P11-R11 -> 0 | R11: 1100
B12: 46085.958 | C12: 25450 | E12: =C12+D12-F12 -> 4400 | F12: 21050 | H12: 46085.958 | I12: 24000 | K12: =I12+J12-L12 -> 300 | L12: 23700 | N12: 46085.958 | O12: 1100 | Q12: =O12+P12-R12 -> 0 | R12: 1100
B13: 46086.958 | C13: 21050 | E13: =C13+D13-F13 -> 5800 | F13: 15250 | H13: 46086.958 | I13: 23700 | K13: =I13+J13-L13 -> 600 | L13: 23100 | N13: 46086.958 | O13: 1100 | Q13: =O13+P13-R13 -> 0 | R13: 1100
B14: 46087.958 | C14: 15250 | E14: =C14+D14-F14 -> 4550 | F14: 10700 | H14: 46087.958 | I14: 23100 | K14: =I14+J14-L14 -> 500 | L14: 22600 | N14: 46087.958 | O14: 1100 | Q14: =O14+P14-R14 -> 0 | R14: 1100
B15: 46088.958 | C15: 10700 | E15: =C15+D15-F15 -> 3700 | F15: 7000 | H15: 46088.958 | I15: 22600 | K15: =I15+J15-L15 -> 100 | L15: 22500 | N15: 46088.958 | O15: 1100 | Q15: =O15+P15-R15 -> 0 | R15: 1100
B16: 46089.958 | C16: 7000 | D16: 44600 | E16: =C16+D16-F16 -> 3400 | F16: 48200 | H16: 46089.958 | I16: 22500 | K16: =I16+J16-L16 -> 200 | L16: 22300 | N16: 46089.958 | O16: 1100 | Q16: =O16+P16-R16 -> 0 | R16: 1100
B17: 46090.958 | C17: 48200 | E17: =C17+D17-F17 -> 4300 | F17: 43900 | H17: 46090.958 | I17: 22300 | K17: =I17+J17-L17 -> 400 | L17: 21900 | N17: 46090.958 | O17: 1100 | Q17: =O17+P17-R17 -> 0 | R17: 1100
B18: 46091.958 | C18: 43900 | E18: =C18+D18-F18 -> 0 | F18: 43900 | H18: 46091.958 | I18: 21900 | K18: =I18+J18-L18 -> 0 | L18: 21900 | N18: 46091.958 | O18: 1100 | Q18: =O18+P18-R18 -> 0 | R18: 1100
B19: 46092.958 | C19: 43950 | E19: =C19+D19-F19 -> 0 | F19: 43950 | H19: 46092.958 | I19: 10750 | K19: =I19+J19-L19 -> 0 | L19: 10750 | N19: 46092.958 | O19: 1100 | Q19: =O19+P19-R19 -> 0 | R19: 1100
B20: 46093.958 | C20: 43950 | E20: =C20+D20-F20 -> 0 | F20: 43950 | H20: 46093.958 | I20: 10750 | K20: =I20+J20-L20 -> 0 | L20: 10750 | N20: 46093.958 | O20: 1100 | Q20: =O20+P20-R20 -> 0 | R20: 1100
B21: 46094.958 | C21: 43950 | E21: =C21+D21-F21 -> 15950 | F21: 28000 | H21: 46094.958 | I21: 10750 | K21: =I21+J21-L21 -> -24150 | L21: 34900 | N21: 46094.958 | O21: 1100 | Q21: =O21+P21-R21 -> 0 | R21: 1100
B22: 46095.958 | C22: 28000 | E22: =C22+D22-F22 -> 3450 | F22: 24550 | H22: 46095.958 | I22: 34900 | K22: =I22+J22-L22 -> 300 | L22: 34600 | N22: 46095.958 | O22: 1100 | Q22: =O22+P22-R22 -> 0 | R22: 1100
B23: 46096.958 | C23: 24550 | E23: =C23+D23-F23 -> 4050 | F23: 20500 | H23: 46096.958 | I23: 34600 | K23: =I23+J23-L23 -> 200 | L23: 34400 | N23: 46096.958 | O23: 1100 | Q23: =O23+P23-R23 -> 0 | R23: 1100
E24: =C24+D24-F24 -> 0 | K24: =I24+J24-L24 -> 0 | Q24: =O24+P24-R24 -> 0
E25: =C25+D25-F25 -> 0 | K25: =I25+J25-L25 -> 0 | Q25: =O25+P25-R25 -> 0
E26: =C26+D26-F26 -> 0 | K26: =I26+J26-L26 -> 0 | Q26: =O26+P26-R26 -> 0
E27: =C27+D27-F27 -> 0 | K27: =I27+J27-L27 -> 0 | Q27: =O27+P27-R27 -> 0
E28: =C28+D28-F28 -> 0 | K28: =I28+J28-L28 -> 0 | Q28: =O28+P28-R28 -> 0
E29: =C29+D29-F29 -> 0 | K29: =I29+J29-L29 -> 0 | Q29: =O29+P29-R29 -> 0
E30: =C30+D30-F30 -> 0 | K30: =I30+J30-L30 -> 0 | Q30: =O30+P30-R30 -> 0
E31: =C31+D31-F31 -> 0 | K31: =I31+J31-L31 -> 0 | Q31: =O31+P31-R31 -> 0
E32: =C32+D32-F32 -> 0 | K32: =I32+J32-L32 -> 0 | Q32: =O32+P32-R32 -> 0
E33: =C33+D33-F33 -> 0 | K33: =I33+J33-L33 -> 0 | Q33: =O33+P33-R33 -> 0
E34: =C34+D34-F34 -> 0 | K34: =I34+J34-L34 -> 0 | Q34: =O34+P34-R34 -> 0
E35: =C35+D35-F35 -> 0 | K35: =I35+J35-L35 -> 0 | Q35: =O35+P35-R35 -> 0
... E37: =C37+D37-F37 -> 0 | K37: =I37+J37-L37 -> 0 | Q37: =O37+P37-R37 -> 0
C38: 20500 | E38: =C38+D38-F38 -> 0 | F38: 20500 | I38: 34400 | K38: =I38+J38-L38 -> 0 | L38: 34400 | O38: 1100 | Q38: =O38+P38-R38 -> 0 | R38: 1100
F40: =IF(C38>0,F38,F37) -> 20500 | L40: =IF(I38>0,L38,L37) -> 34400 | R40: =IF(O38>0,R38,R37) -> 1100

Sheet Customers' Ledger
A1: CORPORATE CUSTOMERS STATEMENT FOR THE MONTH
A2: S/N | B2: CUSTOMER'S NAME | C2: OPENING BALANCE | E2: LODGEMENT DATE | F2: BANK | G2: AMOUNT LODGED | I2: VALUE OF PRODUCT SOLD | J2: CLOSING BALANCE
A3: 1 | J3: =C3+G3-I3 -> 0
J4: =C4+G4-I4 -> 0
J5: =C5+G5-I5 -> 0
J6: =C6+G6-I6 -> 0
J7: =C7+G7-I7 -> 0
J8: =C8+G8-I8 -> 0
J9: =C9+G9-I9 -> 0
A10: 2 | J10: =C10+G10-I10 -> 0
J11: =C11+G11-I11 -> 0
J12: =C12+G12-I12 -> 0
J13: =C13+G13-I13 -> 0
J14: =C14+G14-I14 -> 0
J15: =C15+G15-I15 -> 0
J16: =C16+G16-I16 -> 0
A17: 3 | J17: =C17+G17-I17 -> 0
J18: =C18+G18-I18 -> 0
J19: =C19+G19-I19 -> 0
J20: =C20+G20-I20 -> 0
J21: =C21+G21-I21 -> 0
J22: =C22+G22-I22 -> 0
J23: =C23+G23-I23 -> 0
A24: 4 | J24: =C24+G24-I24 -> 0
J25: =C25+G25-I25 -> 0
J26: =C26+G26-I26 -> 0
J27: =C27+G27-I27 -> 0
J28: =C28+G28-I28 -> 0
J29: =C29+G29-I29 -> 0
J30: =C30+G30-I30 -> 0
A31: 5 | J31: =C31+G31-I31 -> 0
J32: =C32+G32-I32 -> 0
J33: =C33+G33-I33 -> 0
J34: =C34+G34-I34 -> 0
J35: =C35+G35-I35 -> 0
J36: =C36+G36-I36 -> 0
J37: =C37+G37-I37 -> 0
A38: 6 | J38: =C38+G38-I38 -> 0
J39: =C39+G39-I39 -> 0
J40: =C40+G40-I40 -> 0
...

Sheet Castro Lubricants
B3: CASTRO OIL AS AT 18/03/2026 -
B4: S/N | C4: ITEM | D4: Litre | E4: OPENING STOCK | F4: PURCHASE | G4: SALES (QUANTITY) | H4: CLOSING STOCK | I4: PRICE (N) | J4: AMOUNT | K4: Date
B5: 1 | C5: POWER RACING 40 10W-50 | D5: 0 | G5: =E5+F5-H5 -> 0 | I5: 0 | J5: =G5*I5 -> 0
B6: 2 | C6: MAGNATEC 5W-30 4L | D6: 0 | G6: =E6+F6-H6 -> 0 | I6: 0 | J6: =G6*I6 -> 0
B7: 3 | C7: ATF DEX II | D7: 0 | G7: =E7+F7-H7 -> 0 | I7: 0 | J7: =G7*I7 -> 0
B8: 4 | C8: RAINOIL SUPREME 1L | D8: 0 | G8: =E8+F8-H8 -> 0 | I8: 0 | J8: =G8*I8 -> 0
B9: 5 | C9: GT X ESSENTIAL 20W-50 1L | D9: 0 | G9: =E9+F9-H9 -> 0 | I9: 0 | J9: =G9*I9 -> 0
B10: 6 | C10: GT X ESSENTIAL 15W-40 4L | D10: 0 | G10: =E10+F10-H10 -> 0 | I10: 0 | J10: =G10*I10 -> 0
B11: 7 | C11: GT X ESSENTIAL 15W-40 5L | D11: 0 | G11: =E11+F11-H11 -> 0 | I11: 0 | J11: =G11*I11 -> 0
B12: 8 | C12: MOTOR OIL SAE 40 | D12: 0 | G12: =E12+F12-H12 -> 0 | I12: 0 | J12: =G12*I12 -> 0
B13: 9 | C13: INJECTOR CLEANER | D13: 0 | G13: =E13+F13-H13 -> 0 | I13: 0 | J13: =G13*I13 -> 0
B14: 10 | C14: BRAKE FLUID DOT 4 0.5L | D14: 0 | G14: =E14+F14-H14 -> 0 | I14: 0 | J14: =G14*I14 -> 0
B15: 11 | C15: POWER MAX HD-40 (RETAIL OIL) | D15: 0 | G15: =E15+F15-H15 -> 0 | I15: 0 | J15: =G15*I15 -> 0
B16: 12 | C16: MAGNATEC 5W-30 A5 | D16: 0 | G16: =E16+F16-H16 -> 0 | I16: 0 | J16: =G16*I16 -> 0
... B25: 21 | C25: MAGNATEC 10W-40 4L | D25: 0 | G25: =E25+F25-H25 -> 0 | I25: 0 | J25: =G25*I25 -> 0
G26: =E26+F26-H26 -> 0
G27: =E27+F27-H27 -> 0
G28: =E28+F28-H28 -> 0
G29: =E29+F29-H29 -> 0
E30: =SUM(E5:E29) -> 0 | F30: =SUM(F5:F29) -> 0 | G30: =SUM(G5:G29) -> 0 | H30: =SUM(H5:H29) -> 0 | I30: TOTAL | J30: =SUM(J5:J29) -> 0
I31: LODGED
I32: LODGED
I33: LODGED
I34: LODGED
I35: LODGED
J36: =J30-SUM(J31:J35) -> 0

Sheet Sheet1 (2)
B2: Name of Station
B3: Prepared By
B4: Date of Preparation
B7: SALES DATE | C7: TOTAL SALES | E7: CASH SALES | G7: CREDIT SALES | I7: ANALYSIS OF POS BY BANKS | P7: P.O.S | Q7: EXPENSES | R7: EXPECTED LODGEMENT | S7: ACTUAL LODGEMENT | T7: TELLER NO | U7: LODGEMENT DATE | V7: AREA MANAGERS COMMENT
I8: Zenith Bank | J8: Diamond Bank | K8: Stanbic Bank | L8: GT Bank | M8: Providus Bank | N8: Access Bank | O8: Fidelity Bank
C10: =E10+G10+P10 -> 0
C11: =E11+G11+P11 -> 0
C12: =E12+G12+P12 -> 0
C13: =E13+G13+P13 -> 0
C14: =E14+G14+P14 -> 0
C15: =E15+G15+P15 -> 0
C16: =E16+G16+P16 -> 0
C17: =E17+G17+P17 -> 0
C18: =E18+G18+P18 -> 0
C19: =E19+G19+P19 -> 0
C20: =E20+G20+P20 -> 0
C21: =E21+G21+P21 -> 0
... C108: =E108+G108+P108 -> 0
